Workbook

Sheet Vocabulary
A1: Madinah Arabic — Book 1 Vocabulary
A2: All Arabic words taught in the course, in lesson order. One row per word.
A4: Session | B4: Lesson | C4: Part | D4: Lesson Topic (Arabic) | E4: Lesson Topic (English) | F4: Arabic | G4: English Meaning | H4: Indefinite Form | I4: Icon | J4: In Quran | K4: Source
A5: 1 | B5: 1.1 | C5: A | D5: مَا هَذَا؟ | E5: What Is This? (Part 1) | F5: هَذَا | G5: this (m.) | J5: No | K5: Word card
A6: 1 | B6: 1.1 | C6: A | D6: مَا هَذَا؟ | E6: What Is This? (Part 1) | F6: مَا | G6: what | J6: No | K6: Word card
A7: 1 | B7: 1.1 | C7: A | D7: مَا هَذَا؟ | E7: What Is This? (Part 1) | F7: كِتَابٌ | G7: book | I7: 📖 | J7: Yes | K7: Word card
A8: 1 | B8: 1.1 | C8: A | D8: مَا هَذَا؟ | E8: What Is This? (Part 1) | F8: قَلَمٌ | G8: pen | I8: 🖊️ | J8: Yes | K8: Word card
A9: 1 | B9: 1.1 | C9: A | D9: مَا هَذَا؟ | E9: What Is This? (Part 1) | F9: مِفْتَاحٌ | G9: key | I9: 🔑 | J9: Yes | K9: Word card
A10: 1 | B10: 1.1 | C10: A | D10: مَا هَذَا؟ | E10: What Is This? (Part 1) | F10: بَابٌ | G10: door | I10: 🚪 | J10: Yes | K10: Word card
A11: 2 | B11: 1.1 | C11: B | D11: مَا هَذَا؟ | E11: What Is This? (Part 2) | F11: بَيْتٌ | G11: house | I11: 🏠 | J11: Yes | K11: Word card
A12: 2 | B12: 1.1 | C12: B | D12: مَا هَذَا؟ | E12: What Is This? (Part 2) | F12: مَسْجِدٌ | G12: mosque | I12: 🕌 | J12: Yes | K12: Word card
A13: 2 | B13: 1.1 | C13: B | D13: مَا هَذَا؟ | E13: What Is This? (Part 2) | F13: نَجْمٌ | G13: star | I13: ⭐ | J13: Yes | K13: Word card
A14: 2 | B14: 1.1 | C14: B | D14: مَا هَذَا؟ | E14: What Is This? (Part 2) | F14: حَجَرٌ | G14: stone | I14: 🪨 | J14: Yes | K14: Word card
A15: 3 | B15: 1.1 | C15: C | D15: الْحَيَوَانَاتُ | E15: Animals | F15: كَلْبٌ | G15: dog | I15: 🐕 | J15: Yes | K15: Word card
A16: 3 | B16: 1.1 | C16: C | D16: الْحَيَوَانَاتُ | E16: Animals | F16: ذِئْبٌ | G16: wolf | I16: 🐺 | J16: Yes | K16: Word card
A17: 3 | B17: 1.1 | C17: C | D17: الْحَيَوَانَاتُ | E17: Animals | F17: حِمَارٌ | G17: donkey | I17: 🫏 | J17: Yes | K17: Word card
A18: 3 | B18: 1.1 | C18: C | D18: الْحَيَوَانَاتُ | E18: Animals | F18: جَمَلٌ | G18: camel | I18: 🐪 | J18: Yes | K18: Word card
... A23: 3 | B23: 1.1 | C23: C | D23: الْحَيَوَانَاتُ | E23: Animals | F23: عَنْكَبُوتٌ | G23: spider | I23: 🕷️ | J23: Yes | K23: Word card
A24: 3 | B24: 1.1 | C24: C | D24: الْحَيَوَانَاتُ | E24: Animals | F24: وَ | G24: and | J24: No | K24: Word card
A25: 4 | B25: 1.1 | C25: D | D25: الْمِهَنُ وَالْمَلَابِسُ | E25: Professions & Clothing | F25: مَنْ | G25: who | J25: Yes | K25: Word card
A26: 4 | B26: 1.1 | C26: D | D26: الْمِهَنُ وَالْمَلَابِسُ | E26: Professions & Clothing | F26: إِمَامٌ | G26: imam | I26: 👳🏼‍♂️ | J26: Yes | K26: Word card
A27: 4 | B27: 1.1 | C27: D | D27: الْمِهَنُ وَالْمَلَابِسُ | E27: Professions & Clothing | F27: رَسُولٌ | G27: messenger | J27: Yes | K27: Word card
A28: 4 | B28: 1.1 | C28: D | D28: الْمِهَنُ وَالْمَلَابِسُ | E28: Professions & Clothing | F28: تَاجِرٌ | G28: merchant | I28: 🧑‍💼 | J28: No | K28: Word card
A29: 4 | B29: 1.1 | C29: D | D29: الْمِهَنُ وَالْمَلَابِسُ | E29: Professions & Clothing | F29: سِرَاجٌ | G29: lamp | I29: 🪔 | J29: Yes | K29: Word card
A30: 4 | B30: 1.1 | C30: D | D30: الْمِهَنُ وَالْمَلَابِسُ | E30: Professions & Clothing | F30: قَمِيصٌ | G30: shirt | I30: 👕 | J30: Yes | K30: Word card
A31: 5 | B31: 1.1 | C31: E | D31: أَسْئِلَةُ نَعَمْ وَلَا | E31: Yes/No Questions | F31: نَعَمْ | G31: yes | J31: No | K31: Word card
A32: 5 | B32: 1.1 | C32: E | D32: أَسْئِلَةُ نَعَمْ وَلَا | E32: Yes/No Questions | F32: لَا | G32: no | J32: Yes | K32: Word card
A33: 5 | B33: 1.1 | C33: E | D33: أَسْئِلَةُ نَعَمْ وَلَا | E33: Yes/No Questions | F33: أَهَذَا | G33: Is this...? (m.) | J33: No | K33: Word card
A34: 5 | B34: 1.1 | C34: E | D34: أَسْئِلَةُ نَعَمْ وَلَا | E34: Yes/No Questions | F34: هَلْ | G34: Is...? (yes/no question) | J34: No | K34: Word card
A35: 5 | B35: 1.1 | C35: E | D35: أَسْئِلَةُ نَعَمْ وَلَا | E35: Yes/No Questions | F35: قِطٌّ | G35: cat | I35: 🐈 | J35: No | K35: Word card
A36: 6 | B36: 1.2 | C36: A | D36: ذَلِكَ — That Is... | E36: Far Demonstratives (Part 1) | F36: ذَلِكَ | G36: that (m., far) | J36: No | K36: Word card
A37: 6 | B37: 1.2 | C37: A | D37: ذَلِكَ — That Is... | E37: Far Demonstratives (Part 1) | F37: سَرِيرٌ | G37: bed | I37: 🛏️ | J37: Yes | K37: Word card
A38: 6 | B38: 1.2 | C38: A | D38: ذَلِكَ — That Is... | E38: Far Demonstratives (Part 1) | F38: كُرْسِيٌّ | G38: chair | I38: 🪑 | J38: Yes | K38: Word card
A39: 6 | B39: 1.2 | C39: A | D39: ذَلِكَ — That Is... | E39: Far Demonstratives (Part 1) | F39: مَكْتَبٌ | G39: desk/office | I39: 🗂️ | J39: No | K39: Word card
A40: 6 | B40: 1.2 | C40: A | D40: ذَلِكَ — That Is... | E40: Far Demonstratives (Part 1) | F40: جِدَارٌ | G40: wall | I40: 🧱 | J40: Yes | K40: Word card
A41: 7 | B41: 1.2 | C41: B | D41: ذَلِكَ — That Is... | E41: Far Demonstratives (Part 2) | F41: وَلَدٌ | G41: boy | I41: 👦 | J41: Yes | K41: Word card
A42: 7 | B42: 1.2 | C42: B | D42: ذَلِكَ — That Is... | E42: Far Demonstratives (Part 2) | F42: رَجُلٌ | G42: man | I42: 👨 | J42: Yes | K42: Word card
A43: 7 | B43: 1.2 | C43: B | D43: ذَلِكَ — That Is... | E43: Far Demonstratives (Part 2) | F43: طَالِبٌ | G43: student (m.) | I43: 👨‍🎓 | J43: No | K43: Word card
A44: 7 | B44: 1.2 | C44: B | D44: ذَلِكَ — That Is... | E44: Far Demonstratives (Part 2) | F44: مُدَرِّسٌ | G44: teacher (m.) | I44: 👨‍🏫 | J44: No | K44: Word card
A45: 8 | B45: 1.3 | C45: A | D45: الـ — The Definite Article (Part 1) | E45: Making Nouns Definite | F45: الْكِتَابُ | G45: the book | H45: كِتَابٌ | I45: 📖 | J45: Yes | K45: Word card
...

Sheet Lessons
A1: Lesson-by-Lesson Grammar Notes
A3: Session | B3: Lesson | C3: Part | D3: Topic (Arabic) | E3: Topic (English) | F3: Words | G3: Grammar Note
A4: 1 | B4: 1.1 | C4: A | D4: مَا هَذَا؟ | E4: What Is This? (Part 1) | F4: =COUNTIFS(Vocabulary!$A$5:$A$154,A4,Vocabulary!$K$5:$K$154,"Word card") -> 6 | G4: هَذَا means "this" for masculine objects. مَا هَذَا؟ = What is this? Answer: هَذَا كِتَابٌ. Nouns take ـٌ (tanwīn ḍamm) in the indefinite.
A5: 2 | B5: 1.1 | C5: B | D5: مَا هَذَا؟ | E5: What Is This? (Part 2) | F5: =COUNTIFS(Vocabulary!$A$5:$A$154,A5,Vocabulary!$K$5:$K$154,"Word card") -> 4 | G5: More هَذَا sentences. Nouns ending in ـٌ are indefinite ("a book"). Every Arabic noun has a gender — masculine or feminine.
A6: 3 | B6: 1.1 | C6: C | D6: الْحَيَوَانَاتُ | E6: Animals | F6: =COUNTIFS(Vocabulary!$A$5:$A$154,A6,Vocabulary!$K$5:$K$154,"Word card") -> 10 | G6: More هَذَا/ذَلِكَ with animals. All these nouns are masculine. وَ means "and" — it attaches directly to the next word: هَذَا فِيلٌ وَذَلِكَ جَمَلٌ. Note: عَنْكَبُوتٌ (spider) can be treated as masculine or feminine; we use هَذَا with it here.
A7: 4 | B7: 1.1 | C7: D | D7: الْمِهَنُ وَالْمَلَابِسُ | E7: Professions & Clothing | F7: =COUNTIFS(Vocabulary!$A$5:$A$154,A7,Vocabulary!$K$5:$K$154,"Word card") -> 6 | G7: مَنْ هَذَا؟ = Who is this? Used for people: مَنْ هَذَا؟ هَذَا إِمَامٌ. مَا هَذَا؟ هَذَا قَمِيصٌ.
A8: 5 | B8: 1.1 | C8: E | D8: أَسْئِلَةُ نَعَمْ وَلَا | E8: Yes/No Questions | F8: =COUNTIFS(Vocabulary!$A$5:$A$154,A8,Vocabulary!$K$5:$K$154,"Word card") -> 5 | G8: Both أَ and هَلْ are yes/no question particles — they are interchangeable. أَهَذَا مَسْجِدٌ؟ = هَلْ هَذَا مَسْجِدٌ؟ = Is this a mosque? Answer: نَعَمْ، هَذَا مَسْجِدٌ (Yes) or لَا، هَذَا بَيْتٌ (No). أَ attaches directly to the next word; هَلْ stands alone.
A9: 6 | B9: 1.2 | C9: A | D9: ذَلِكَ — That Is... | E9: Far Demonstratives (Part 1) | F9: =COUNTIFS(Vocabulary!$A$5:$A$154,A9,Vocabulary!$K$5:$K$154,"Word card") -> 5 | G9: ذَلِكَ = "that" for masculine objects far away. وَ ("and") joins the two sentences: هَذَا مَكْتَبٌ وَذَلِكَ سَرِيرٌ.
A10: 7 | B10: 1.2 | C10: B | D10: ذَلِكَ — That Is... | E10: Far Demonstratives (Part 2) | F10: =COUNTIFS(Vocabulary!$A$5:$A$154,A10,Vocabulary!$K$5:$K$154,"Word card") -> 4 | G10: Practice هَذَا and ذَلِكَ with people. مَنْ هَذَا؟ = Who is this? (used for people, not objects). وَ joins two sentences: هَذَا طَالِبٌ وَذَلِكَ مُدَرِّسٌ.
A11: 8 | B11: 1.3 | C11: A | D11: الـ — The Definite Article (Part 1) | E11: Making Nouns Definite | F11: =COUNTIFS(Vocabulary!$A$5:$A$154,A11,Vocabulary!$K$5:$K$154,"Word card") -> 4 | G11: الـ makes a noun definite: كِتَابٌ → الْكِتَابُ. The ـٌ disappears, replaced by ـُ. With "moon letters" الـ is fully pronounced: الْبَيْتُ.
A12: 9 | B12: 1.3 | C12: B | D12: الـ — Sun & Moon Letters | E12: Sun Letters (Part 2) | F12: =COUNTIFS(Vocabulary!$A$5:$A$154,A12,Vocabulary!$K$5:$K$154,"Word card") -> 4 | G12: With "sun letters" (ت،ث،د،ذ،ر،ز،س،ش،ص،ض،ط،ظ،ل،ن) the ل of الـ assimilates. Written but not pronounced — the first letter doubles instead.
A13: 10 | B13: 1.4 | C13: A | D13: الصِّفَاتُ — Adjectives (Part 1) | E13: Describing with Adjectives | F13: =COUNTIFS(Vocabulary!$A$5:$A$154,A13,Vocabulary!$K$5:$K$154,"Word card") -> 4 | G13: Adjectives come AFTER the noun and must match it. Definite noun → definite adjective. Indefinite noun → indefinite adjective.
A14: 11 | B14: 1.4 | C14: B | D14: الصِّفَاتُ — More Adjectives (Part 2) | E14: More Adjectives | F14: =COUNTIFS(Vocabulary!$A$5:$A$154,A14,Vocabulary!$K$5:$K$154,"Word card") -> 4 | G14: More masculine adjectives. The adjective follows the noun and takes the same tanwīn.
A15: 12 | B15: 1.5 | C15: A | D15: حُرُوفُ الْجَرِّ (Part 1) | E15: Prepositions: في، عَلَى، مِنْ، إِلَى | F15: =COUNTIFS(Vocabulary!$A$5:$A$154,A15,Vocabulary!$K$5:$K$154,"Word card") -> 4 | G15: After a preposition, the noun takes genitive case — it loses ـٌ and takes ـٍ (or ـِ if definite).
... A27: 24 | B27: 1.10 | C27: B | D27: مُرَاجَعَةٌ — Book 1 Review | E27: Book 1 Revision | F27: =COUNTIFS(Vocabulary!$A$5:$A$154,A27,Vocabulary!$K$5:$K$154,"Word card") -> 4 | G27: Review all Book 1 patterns: هَذَا/ذَلِكَ/هَذِهِ/تِلْكَ, الـ, adjective agreement, prepositions, pronouns, iḍāfa, الَّذِي.

Sheet Summary
A1: Course Summary
A5: Sessions (lessons) | B5: =COUNTA(Lessons!$A$4:$A$27) -> 24
A6: Total Arabic entries | B6: =COUNTA(Vocabulary!$F$5:$F$154) -> 150
A7: on New Words cards | B7: =COUNTIF(Vocabulary!$K$5:$K$154,"Word card") -> 118
A8: grammar & exercises only | B8: =COUNTIF(Vocabulary!$K$5:$K$154,"Grammar & exercises") -> 0
A9: Quran verse tiles | B9: =COUNTIF(Vocabulary!$K$5:$K$154,"Quran verse tile") -> 32
A10: Distinct Arabic entries | B10: =SUMPRODUCT((Vocabulary!$F$5:$F$154<>"")/COUNTIF(Vocabulary!$F$5:$F$154,Vocabulary!$F$5:$F$154&"")) -> 143
A11: Words with a Quran verse | B11: =COUNTIF(Vocabulary!$J$5:$J$154,"Yes") -> 84
A12: Words with an icon | B12: =COUNTA(Vocabulary!$I$5:$I$154) -> 68
A13: Definite/indefinite pairs | B13: =COUNTA(Vocabulary!$H$5:$H$154) -> 8
A14: Avg word-card words / lesson | B14: =ROUND(B7/B5,1) -> 4.9
A16: Source: generated directly from SESSIONS in src/App.jsx. "In Quran" = the word has a linked verse in QURAN_CONNECTIONS. "Indefinite Form" is filled only for the definite-article lessons, which teach e.g. الْكِتَابُ against كِتَابٌ. Source column: "Word card" = listed in the session's vocab and drilled; "Grammar & exercises" (amber) = taught in a grammar note or exercise prompt but NOT on the word cards, so never drilled — this includes the demonstratives هَذَا / ذَلِكَ / هَذِهِ / تِلْكَ; "Quran verse tile" = pre-placed gold tiles from a verse.
